---
title: Deneyin... Yakala... Finally ekstresi
description: Visual Basic try/catch/finally deyimleriyle özel durum işlemeyi kullanmayı öğrenin.
ms.date: 12/07/2018
f1_keywords:
- vb.Try...Catch...Finally
- vb.when
- vb.Finally
- vb.Catch
- vb.Try
helpviewer_keywords:
- Try...Catch...Finally statements
- Try statement [Visual Basic]
- try-catch exception handling, Try...Catch...Finally statements
- error handling, while running code
- Try statement [Visual Basic], Try...Catch...Finally
- Finally keyword [Visual Basic], Try...Catch...Finally
- Catch statement [Visual Basic]
- When keyword [Visual Basic]
- Visual Basic code, handling errors while running
- structured exception handling, Try...Catch...Finally statements
ms.assetid: d6488026-ccb3-42b8-a810-0d97b9d6472b
ms.openlocfilehash: bb6f17f7ce88caea0b9d30ec880194f2bb71c6a6
ms.sourcegitcommit: 5f236cd78cf09593c8945a7d753e0850e96a0b80
ms.translationtype: MT
ms.contentlocale: tr-TR
ms.lasthandoff: 01/07/2020
ms.locfileid: "75705775"
---
# <a name="trycatchfinally-statement-visual-basic"></a><span data-ttu-id="8cd1e-103">Try...Catch...Finally Deyimi (Visual Basic)</span><span class="sxs-lookup"><span data-stu-id="8cd1e-103">Try...Catch...Finally Statement (Visual Basic)</span></span>

<span data-ttu-id="8cd1e-104">Kodu çalıştırmaya devam ederken, belirli bir kod bloğunda oluşabilecek bazı veya tüm olası hataları işlemek için bir yol sağlar.</span><span class="sxs-lookup"><span data-stu-id="8cd1e-104">Provides a way to handle some or all possible errors that may occur in a given block of code, while still running code.</span></span>

## <a name="syntax"></a><span data-ttu-id="8cd1e-105">Sözdizimi</span><span class="sxs-lookup"><span data-stu-id="8cd1e-105">Syntax</span></span>

```vb
Try
    [ tryStatements ]
    [ Exit Try ]
[ Catch [ exception [ As type ] ] [ When expression ]
    [ catchStatements ]
    [ Exit Try ] ]
[ Catch ... ]
[ Finally
    [ finallyStatements ] ]
End Try
```

## <a name="parts"></a><span data-ttu-id="8cd1e-106">Bölümler</span><span class="sxs-lookup"><span data-stu-id="8cd1e-106">Parts</span></span>

|<span data-ttu-id="8cd1e-107">Terim</span><span class="sxs-lookup"><span data-stu-id="8cd1e-107">Term</span></span>|<span data-ttu-id="8cd1e-108">Tanım</span><span class="sxs-lookup"><span data-stu-id="8cd1e-108">Definition</span></span>|
|---|---|
|`tryStatements`|<span data-ttu-id="8cd1e-109">İsteğe bağlı.</span><span class="sxs-lookup"><span data-stu-id="8cd1e-109">Optional.</span></span> <span data-ttu-id="8cd1e-110">Bir hatanın gerçekleşebileceği deyimler.</span><span class="sxs-lookup"><span data-stu-id="8cd1e-110">Statement(s) where an error can occur.</span></span> <span data-ttu-id="8cd1e-111">Bileşik bir ifade olabilir.</span><span class="sxs-lookup"><span data-stu-id="8cd1e-111">Can be a compound statement.</span></span>|
|`Catch`|<span data-ttu-id="8cd1e-112">İsteğe bağlı.</span><span class="sxs-lookup"><span data-stu-id="8cd1e-112">Optional.</span></span> <span data-ttu-id="8cd1e-113">Çoklu `Catch` blokları izin veriliyor.</span><span class="sxs-lookup"><span data-stu-id="8cd1e-113">Multiple `Catch` blocks permitted.</span></span> <span data-ttu-id="8cd1e-114">`Try` bloğunu işlerken bir özel durum oluşursa, her `Catch` bir durum, özel durumu (atılan özel durumu temsil eden `exception`) nasıl işleyeceğini öğrenmek için metin sırasına göre incelenir.</span><span class="sxs-lookup"><span data-stu-id="8cd1e-114">If an exception occurs when processing the `Try` block, each `Catch` statement is examined in textual order to determine whether it handles the exception, with `exception` representing the exception that has been thrown.</span></span>|
|`exception`|<span data-ttu-id="8cd1e-115">İsteğe bağlı.</span><span class="sxs-lookup"><span data-stu-id="8cd1e-115">Optional.</span></span> <span data-ttu-id="8cd1e-116">Herhangi bir değişken adı.</span><span class="sxs-lookup"><span data-stu-id="8cd1e-116">Any variable name.</span></span> <span data-ttu-id="8cd1e-117">`exception` ilk değeri oluşturulan hatanın değeridir.</span><span class="sxs-lookup"><span data-stu-id="8cd1e-117">The initial value of `exception` is the value of the thrown error.</span></span> <span data-ttu-id="8cd1e-118">Yakalanan hatayı belirtmek için `Catch` ile birlikte kullanılır.</span><span class="sxs-lookup"><span data-stu-id="8cd1e-118">Used with `Catch` to specify the error caught.</span></span> <span data-ttu-id="8cd1e-119">Atlanırsa, `Catch` ifade herhangi bir özel durumu yakalar.</span><span class="sxs-lookup"><span data-stu-id="8cd1e-119">If omitted, the `Catch` statement catches any exception.</span></span>|
|`type`|<span data-ttu-id="8cd1e-120">İsteğe bağlı.</span><span class="sxs-lookup"><span data-stu-id="8cd1e-120">Optional.</span></span> <span data-ttu-id="8cd1e-121">Sınıf filtresinin türünü belirtir.</span><span class="sxs-lookup"><span data-stu-id="8cd1e-121">Specifies the type of class filter.</span></span> <span data-ttu-id="8cd1e-122">`exception` değeri `type` veya türetilmiş bir tür tarafından belirtilen türde ise, tanımlayıcı özel durum nesnesine bağlanır.</span><span class="sxs-lookup"><span data-stu-id="8cd1e-122">If the value of `exception` is of the type specified by `type` or of a derived type, the identifier becomes bound to the exception object.</span></span>|
|`When`|<span data-ttu-id="8cd1e-123">İsteğe bağlı.</span><span class="sxs-lookup"><span data-stu-id="8cd1e-123">Optional.</span></span> <span data-ttu-id="8cd1e-124">`When` yan tümcesinin bulunduğu `Catch` deyimi, yalnızca `expression` `True`değerlendirirken özel durumları yakalar.</span><span class="sxs-lookup"><span data-stu-id="8cd1e-124">A `Catch` statement with a `When` clause catches exceptions only when `expression` evaluates to `True`.</span></span> <span data-ttu-id="8cd1e-125">`When` yan tümcesi yalnızca özel durumun türü denetlendikten sonra uygulanır ve `expression` özel durumu temsil eden tanımlayıcıya başvurabilir.</span><span class="sxs-lookup"><span data-stu-id="8cd1e-125">A `When` clause is applied only after checking the type of the exception, and `expression` may refer to the identifier representing the exception.</span></span>|
|`expression`|<span data-ttu-id="8cd1e-126">İsteğe bağlı.</span><span class="sxs-lookup"><span data-stu-id="8cd1e-126">Optional.</span></span> <span data-ttu-id="8cd1e-127">`Boolean`için örtük olarak dönüştürülebilir olmalıdır.</span><span class="sxs-lookup"><span data-stu-id="8cd1e-127">Must be implicitly convertible to `Boolean`.</span></span> <span data-ttu-id="8cd1e-128">Genel bir filtreyi tanımlayan herhangi bir ifade.</span><span class="sxs-lookup"><span data-stu-id="8cd1e-128">Any expression that describes a generic filter.</span></span> <span data-ttu-id="8cd1e-129">Genellikle hata numarasına göre filtrelemek için kullanılır.</span><span class="sxs-lookup"><span data-stu-id="8cd1e-129">Typically used to filter by error number.</span></span> <span data-ttu-id="8cd1e-130">Hatanın yakalandığı koşulları belirtmek için `When` anahtar sözcüğüyle birlikte kullanılır.</span><span class="sxs-lookup"><span data-stu-id="8cd1e-130">Used with `When` keyword to specify circumstances under which the error is caught.</span></span>|
|`catchStatements`|<span data-ttu-id="8cd1e-131">İsteğe bağlı.</span><span class="sxs-lookup"><span data-stu-id="8cd1e-131">Optional.</span></span> <span data-ttu-id="8cd1e-132">İlişkili `Try` bloğunda oluşan hataları işlemek için deyimler.</span><span class="sxs-lookup"><span data-stu-id="8cd1e-132">Statement(s) to handle errors that occur in the associated `Try` block.</span></span> <span data-ttu-id="8cd1e-133">Bileşik bir ifade olabilir.</span><span class="sxs-lookup"><span data-stu-id="8cd1e-133">Can be a compound statement.</span></span>|
|`Exit Try`|<span data-ttu-id="8cd1e-134">İsteğe bağlı.</span><span class="sxs-lookup"><span data-stu-id="8cd1e-134">Optional.</span></span> <span data-ttu-id="8cd1e-135">`Try...Catch...Finally` yapısını kesen anahtar sözcük.</span><span class="sxs-lookup"><span data-stu-id="8cd1e-135">Keyword that breaks out of the `Try...Catch...Finally` structure.</span></span> <span data-ttu-id="8cd1e-136">Yürütme `End Try` deyimden hemen sonra kodla devam eder.</span><span class="sxs-lookup"><span data-stu-id="8cd1e-136">Execution resumes with the code immediately following the `End Try` statement.</span></span> <span data-ttu-id="8cd1e-137">`Finally` deyimin yürütülmesi devam eder.</span><span class="sxs-lookup"><span data-stu-id="8cd1e-137">The `Finally` statement will still be executed.</span></span> <span data-ttu-id="8cd1e-138">`Finally` bloklarında izin verilmez.</span><span class="sxs-lookup"><span data-stu-id="8cd1e-138">Not allowed in `Finally` blocks.</span></span>|
|`Finally`|<span data-ttu-id="8cd1e-139">İsteğe bağlı.</span><span class="sxs-lookup"><span data-stu-id="8cd1e-139">Optional.</span></span> <span data-ttu-id="8cd1e-140">`Finally` bloğu her zaman yürütme, `Try...Catch` bildiriminin herhangi bir parçasını terk ettiğinde yürütülür.</span><span class="sxs-lookup"><span data-stu-id="8cd1e-140">A `Finally` block is always executed when execution leaves any part of the `Try...Catch` statement.</span></span>|
|`finallyStatements`|<span data-ttu-id="8cd1e-141">İsteğe bağlı.</span><span class="sxs-lookup"><span data-stu-id="8cd1e-141">Optional.</span></span> <span data-ttu-id="8cd1e-142">Diğer tüm hata işlemeden sonra yürütülen deyimler.</span><span class="sxs-lookup"><span data-stu-id="8cd1e-142">Statement(s) that are executed after all other error processing has occurred.</span></span>|
|`End Try`|<span data-ttu-id="8cd1e-143">`Try...Catch...Finally` yapısını sonlandırır.</span><span class="sxs-lookup"><span data-stu-id="8cd1e-143">Terminates the `Try...Catch...Finally` structure.</span></span>|

## <a name="remarks"></a><span data-ttu-id="8cd1e-144">Açıklamalar</span><span class="sxs-lookup"><span data-stu-id="8cd1e-144">Remarks</span></span>

<span data-ttu-id="8cd1e-145">Belirli bir özel durumun kodun belirli bir bölümü sırasında oluşması beklendiğinde, kodu bir `Try` bloğuna koyun ve bir `Catch` bloğunu kullanarak denetimi koruyabilir ve hata oluşursa özel durumu işleyebilir.</span><span class="sxs-lookup"><span data-stu-id="8cd1e-145">If you expect that a particular exception might occur during a particular section of code, put the code in a `Try` block and use a `Catch` block to retain control and handle the exception if it occurs.</span></span>

<span data-ttu-id="8cd1e-146">`Try…Catch` bir ifade, çeşitli özel durumlar için işleyiciler belirten bir veya daha fazla `Catch` yan tümcesi tarafından izlenen bir `Try` bloğundan oluşur.</span><span class="sxs-lookup"><span data-stu-id="8cd1e-146">A `Try…Catch` statement consists of a `Try` block followed by one or more `Catch` clauses, which specify handlers for various exceptions.</span></span> <span data-ttu-id="8cd1e-147">Bir `Try` bloğunda bir özel durum oluştuğunda, Visual Basic özel durumu işleyen `Catch` ifadeye bakar.</span><span class="sxs-lookup"><span data-stu-id="8cd1e-147">When an exception is thrown in a `Try` block, Visual Basic looks for the `Catch` statement that handles the exception.</span></span> <span data-ttu-id="8cd1e-148">Eşleşen bir `Catch` deyimleri bulunamazsa, Visual Basic geçerli yöntemi çağıran yöntemi inceler ve bu şekilde çağrı yığınını devam eder.</span><span class="sxs-lookup"><span data-stu-id="8cd1e-148">If a matching `Catch` statement is not found, Visual Basic examines the method that called the current method, and so on up the call stack.</span></span> <span data-ttu-id="8cd1e-149">`Catch` bloğu bulunmazsa Visual Basic kullanıcıya işlenmeyen bir özel durum iletisi görüntüler ve programın yürütülmesini engeller.</span><span class="sxs-lookup"><span data-stu-id="8cd1e-149">If no `Catch` block is found, Visual Basic displays an unhandled exception message to the user and stops execution of the program.</span></span>

<span data-ttu-id="8cd1e-150">Bir `Try…Catch` bildiriminde birden fazla `Catch` ifadesini kullanabilirsiniz.</span><span class="sxs-lookup"><span data-stu-id="8cd1e-150">You can use more than one `Catch` statement in a `Try…Catch` statement.</span></span> <span data-ttu-id="8cd1e-151">Bunu yaparsanız, `Catch` yan tümcelerinin sıralaması, sırayla incelendikleri için önemlidir.</span><span class="sxs-lookup"><span data-stu-id="8cd1e-151">If you do this, the order of the `Catch` clauses is significant because they are examined in order.</span></span> <span data-ttu-id="8cd1e-152">Daha az özel durumları daha az spesifik olanlardan önce yakalayın.</span><span class="sxs-lookup"><span data-stu-id="8cd1e-152">Catch the more specific exceptions before the less specific ones.</span></span>

<span data-ttu-id="8cd1e-153">Aşağıdaki `Catch` deyimin koşulları en az özeldir ve <xref:System.Exception> sınıfından türetilen tüm özel durumları yakalar.</span><span class="sxs-lookup"><span data-stu-id="8cd1e-153">The following `Catch` statement conditions are the least specific, and will catch all exceptions that derive from the <xref:System.Exception> class.</span></span> <span data-ttu-id="8cd1e-154">Tahmin ettiğiniz tüm özel durumları yakalandıktan sonra, bu varyasyonların her birini `Try...Catch...Finally` yapısında son `Catch` bloğu olarak kullanmanız gerekir.</span><span class="sxs-lookup"><span data-stu-id="8cd1e-154">You should ordinarily use one of these variations as the last `Catch` block in the `Try...Catch...Finally` structure, after catching all the specific exceptions you expect.</span></span> <span data-ttu-id="8cd1e-155">Denetim akışı, bu çeşitlemelerden birini izleyen `Catch` bloğuna hiçbir şekilde ulaşabilirler.</span><span class="sxs-lookup"><span data-stu-id="8cd1e-155">Control flow can never reach a `Catch` block that follows either of these variations.</span></span>

- <span data-ttu-id="8cd1e-156">`type` `Exception`, örneğin: `Catch ex As Exception`</span><span class="sxs-lookup"><span data-stu-id="8cd1e-156">The `type` is `Exception`, for example: `Catch ex As Exception`</span></span>

- <span data-ttu-id="8cd1e-157">Deyimin `exception` değişkeni yok, örneğin: `Catch`</span><span class="sxs-lookup"><span data-stu-id="8cd1e-157">The statement has no `exception` variable, for example: `Catch`</span></span>

<span data-ttu-id="8cd1e-158">`Try…Catch…Finally` bir ifade başka bir `Try` bloğunda iç içe olduğunda, Visual Basic ilk olarak en içteki `Try` bloğundaki her bir `Catch` ekstresini inceler.</span><span class="sxs-lookup"><span data-stu-id="8cd1e-158">When a `Try…Catch…Finally` statement is nested in another `Try` block, Visual Basic first examines each `Catch` statement in the innermost `Try` block.</span></span> <span data-ttu-id="8cd1e-159">Eşleşen `Catch` deyimi bulunamazsa, arama, dış `Try…Catch…Finally` bloğunun `Catch` ifadelerine devam eder.</span><span class="sxs-lookup"><span data-stu-id="8cd1e-159">If no matching `Catch` statement is found, the search proceeds to the `Catch` statements of the outer `Try…Catch…Finally` block.</span></span>

<span data-ttu-id="8cd1e-160">`Try` bloğundan yerel değişkenler, ayrı bloklar olduklarından bir `Catch` bloğunda kullanılamaz.</span><span class="sxs-lookup"><span data-stu-id="8cd1e-160">Local variables from a `Try` block are not available in a `Catch` block because they are separate blocks.</span></span> <span data-ttu-id="8cd1e-161">Birden fazla blok içinde bir değişken kullanmak istiyorsanız, değişkeni `Try...Catch...Finally` yapısı dışında bildirin.</span><span class="sxs-lookup"><span data-stu-id="8cd1e-161">If you want to use a variable in more than one block, declare the variable outside the `Try...Catch...Finally` structure.</span></span>

> [!TIP]
> <span data-ttu-id="8cd1e-162">`Try…Catch…Finally` deyimin bir IntelliSense kod parçacığı olarak kullanılabilir.</span><span class="sxs-lookup"><span data-stu-id="8cd1e-162">The `Try…Catch…Finally` statement is available as an IntelliSense code snippet.</span></span> <span data-ttu-id="8cd1e-163">Kod parçacıkları yöneticisinde, **her biri için, catch, Property, vb**. ve ardından **hata Işleme (özel durumlar)** için kod desenleri ' ni genişletin.</span><span class="sxs-lookup"><span data-stu-id="8cd1e-163">In the Code Snippets Manager, expand **Code Patterns - If, For Each, Try Catch, Property, etc**, and then **Error Handling (Exceptions)**.</span></span> <span data-ttu-id="8cd1e-164">Daha fazla bilgi için [kod parçacıkları](/visualstudio/ide/code-snippets).</span><span class="sxs-lookup"><span data-stu-id="8cd1e-164">For more information, see [Code Snippets](/visualstudio/ide/code-snippets).</span></span>

## <a name="finally-block"></a><span data-ttu-id="8cd1e-165">Finally bloğu</span><span class="sxs-lookup"><span data-stu-id="8cd1e-165">Finally block</span></span>

<span data-ttu-id="8cd1e-166">`Try` yapısından çıkmadan önce çalışması gereken bir veya daha fazla deyim varsa, bir `Finally` bloğu kullanın.</span><span class="sxs-lookup"><span data-stu-id="8cd1e-166">If you have one or more statements that must run before you exit the `Try` structure, use a `Finally` block.</span></span> <span data-ttu-id="8cd1e-167">Denetim, `Try…Catch` yapısını geçirmeden hemen önce `Finally` bloğuna geçer.</span><span class="sxs-lookup"><span data-stu-id="8cd1e-167">Control passes to the `Finally` block just before it passes out of the `Try…Catch` structure.</span></span> <span data-ttu-id="8cd1e-168">Bu, `Try` yapısı içinde herhangi bir yerde bir özel durum gerçekleşse bile geçerlidir.</span><span class="sxs-lookup"><span data-stu-id="8cd1e-168">This is true even if an exception occurs anywhere inside the `Try` structure.</span></span>

<span data-ttu-id="8cd1e-169">Bir `Finally` bloğu, bir özel durum olsa bile yürütülmesi gereken herhangi bir kodu çalıştırmak için yararlıdır.</span><span class="sxs-lookup"><span data-stu-id="8cd1e-169">A `Finally` block is useful for running any code that must execute even if there is an exception.</span></span> <span data-ttu-id="8cd1e-170">`Try...Catch` bloğunun çıkış şeklinden bağımsız olarak denetim `Finally` bloğuna geçirilir.</span><span class="sxs-lookup"><span data-stu-id="8cd1e-170">Control is passed to the `Finally` block regardless of how the `Try...Catch` block exits.</span></span>

<span data-ttu-id="8cd1e-171">`Finally` bloğundaki kod, kodunuz `Try` veya `Catch` bloğunda bir `Return` ifadesiyle karşılaşırsa bile çalışır.</span><span class="sxs-lookup"><span data-stu-id="8cd1e-171">The code in a `Finally` block runs even if your code encounters a `Return` statement in a `Try` or `Catch` block.</span></span> <span data-ttu-id="8cd1e-172">Denetim, aşağıdaki durumlarda bir `Try` veya `Catch` bloğundan karşılık gelen `Finally` bloğuna geçmiyor:</span><span class="sxs-lookup"><span data-stu-id="8cd1e-172">Control does not pass from a `Try` or `Catch` block to the corresponding `Finally` block in the following cases:</span></span>

- <span data-ttu-id="8cd1e-173">`Try` veya `Catch` bloğunda bir [End ifadesiyle](end-statement.md) karşılaşıldı.</span><span class="sxs-lookup"><span data-stu-id="8cd1e-173">An [End Statement](end-statement.md) is encountered in the `Try` or `Catch` block.</span></span>

- <span data-ttu-id="8cd1e-174">`Try` veya `Catch` bloğunda bir <xref:System.StackOverflowException> oluşturulur.</span><span class="sxs-lookup"><span data-stu-id="8cd1e-174">A <xref:System.StackOverflowException> is thrown in the `Try` or `Catch` block.</span></span>

<span data-ttu-id="8cd1e-175">Yürütmeyi `Finally` bloğuna açıkça aktarmak geçerli değildir.</span><span class="sxs-lookup"><span data-stu-id="8cd1e-175">It is not valid to explicitly transfer execution into a `Finally` block.</span></span> <span data-ttu-id="8cd1e-176">Bir özel durum dışında `Finally` bloğunun yürütülmesini aktarma geçerli değildir.</span><span class="sxs-lookup"><span data-stu-id="8cd1e-176">Transferring execution out of a `Finally` block is not valid, except through an exception.</span></span>

<span data-ttu-id="8cd1e-177">Bir `Try` deyimin en az bir `Catch` bloğu yoksa, bir `Finally` bloğu içermesi gerekir.</span><span class="sxs-lookup"><span data-stu-id="8cd1e-177">If a `Try` statement does not contain at least one `Catch` block, it must contain a `Finally` block.</span></span>

> [!TIP]
> <span data-ttu-id="8cd1e-178">Belirli özel durumları yakalamada, `Using` ifade `Try…Finally` bir blok gibi davranır ve bloğundan nasıl çıktığınızda bağımsız olarak kaynakların elden çıkarılmasını garanti eder.</span><span class="sxs-lookup"><span data-stu-id="8cd1e-178">If you do not have to catch specific exceptions, the `Using` statement behaves like a `Try…Finally` block, and guarantees disposal of the resources, regardless of how you exit the block.</span></span> <span data-ttu-id="8cd1e-179">Bu, işlenmeyen bir özel durumla bile geçerlidir.</span><span class="sxs-lookup"><span data-stu-id="8cd1e-179">This is true even with an unhandled exception.</span></span> <span data-ttu-id="8cd1e-180">Daha fazla bilgi için bkz. [using deyimleri](using-statement.md).</span><span class="sxs-lookup"><span data-stu-id="8cd1e-180">For more information, see [Using Statement](using-statement.md).</span></span>

## <a name="exception-argument"></a><span data-ttu-id="8cd1e-181">Özel durum bağımsız değişkeni</span><span class="sxs-lookup"><span data-stu-id="8cd1e-181">Exception argument</span></span>

<span data-ttu-id="8cd1e-182">`Catch` Block `exception` bağımsız değişkeni, <xref:System.Exception> sınıfının veya `Exception` sınıfından türetilen bir sınıfın bir örneğidir.</span><span class="sxs-lookup"><span data-stu-id="8cd1e-182">The `Catch` block `exception` argument is an instance of the <xref:System.Exception> class or a class that derives from the `Exception` class.</span></span> <span data-ttu-id="8cd1e-183">`Exception` sınıfı örneği, `Try` bloğunda oluşan hataya karşılık gelir.</span><span class="sxs-lookup"><span data-stu-id="8cd1e-183">The `Exception` class instance corresponds to the error that occurred in the `Try` block.</span></span>

<span data-ttu-id="8cd1e-184">`Exception` nesnesinin özellikleri, bir özel durumun nedenini ve konumunu belirlemesine yardımcı olur.</span><span class="sxs-lookup"><span data-stu-id="8cd1e-184">The properties of the `Exception` object help to identify the cause and location of an exception.</span></span> <span data-ttu-id="8cd1e-185">Örneğin, <xref:System.Exception.StackTrace%2A> özelliği, özel duruma yol eden çağrılan yöntemleri listeler ve hatanın kodda nerede oluştuğunu bulmanıza yardımcı olur.</span><span class="sxs-lookup"><span data-stu-id="8cd1e-185">For example, the <xref:System.Exception.StackTrace%2A> property lists the called methods that led to the exception, helping you find where the error occurred in the code.</span></span> <span data-ttu-id="8cd1e-186"><xref:System.Exception.Message%2A>, özel durumu açıklayan bir ileti döndürür.</span><span class="sxs-lookup"><span data-stu-id="8cd1e-186"><xref:System.Exception.Message%2A> returns a message that describes the exception.</span></span> <span data-ttu-id="8cd1e-187"><xref:System.Exception.HelpLink%2A> ilişkili bir yardım dosyasının bağlantısını döndürür.</span><span class="sxs-lookup"><span data-stu-id="8cd1e-187"><xref:System.Exception.HelpLink%2A> returns a link to an associated Help file.</span></span> <span data-ttu-id="8cd1e-188"><xref:System.Exception.InnerException%2A>, geçerli özel duruma neden olan `Exception` nesnesini döndürür veya orijinal `Exception`yoksa `Nothing` döndürüyor.</span><span class="sxs-lookup"><span data-stu-id="8cd1e-188"><xref:System.Exception.InnerException%2A> returns the `Exception` object that caused the current exception, or it returns `Nothing` if there is no original `Exception`.</span></span>

## <a name="considerations-when-using-a-trycatch-statement"></a><span data-ttu-id="8cd1e-189">TRY kullanırken dikkat edilecek noktalar... Catch ekstresi</span><span class="sxs-lookup"><span data-stu-id="8cd1e-189">Considerations when using a Try…Catch statement</span></span>

<span data-ttu-id="8cd1e-190">Yalnızca olağan dışı veya beklenmeyen program olaylarının oluşumunu göstermek için bir `Try…Catch` ifadesini kullanın.</span><span class="sxs-lookup"><span data-stu-id="8cd1e-190">Use a `Try…Catch` statement only to signal the occurrence of unusual or unanticipated program events.</span></span> <span data-ttu-id="8cd1e-191">Bunun nedenleri şunları içerir:</span><span class="sxs-lookup"><span data-stu-id="8cd1e-191">Reasons for this include the following:</span></span>

- <span data-ttu-id="8cd1e-192">Çalışma zamanında özel durumları yakalama, ek yük oluşturur ve özel durumların önüne geçmek için önceden denetlenmekten daha yavaş olabilir.</span><span class="sxs-lookup"><span data-stu-id="8cd1e-192">Catching exceptions at runtime creates additional overhead, and is likely to be slower than pre-checking to avoid exceptions.</span></span>

- <span data-ttu-id="8cd1e-193">`Catch` bloğu doğru işlenmezse, özel durum kullanıcılara doğru şekilde raporlanmayabilir.</span><span class="sxs-lookup"><span data-stu-id="8cd1e-193">If a `Catch` block is not handled correctly, the exception might not be reported correctly to users.</span></span>

- <span data-ttu-id="8cd1e-194">Özel durum işleme bir programı daha karmaşık hale getirir.</span><span class="sxs-lookup"><span data-stu-id="8cd1e-194">Exception handling makes a program more complex.</span></span>

<span data-ttu-id="8cd1e-195">Gerçekleşmesi muhtemel bir koşulu denetlemek için her zaman bir `Try…Catch` bildirimine ihtiyacınız yoktur.</span><span class="sxs-lookup"><span data-stu-id="8cd1e-195">You do not always need a `Try…Catch` statement to check for a condition that is likely to occur.</span></span> <span data-ttu-id="8cd1e-196">Aşağıdaki örnek, açmayı denemeden önce bir dosyanın var olup olmadığını denetler.</span><span class="sxs-lookup"><span data-stu-id="8cd1e-196">The following example checks whether a file exists before trying to open it.</span></span> <span data-ttu-id="8cd1e-197">Bu, <xref:System.IO.File.OpenText%2A> metodu tarafından oluşturulan özel durum yakalama gereksinimini azaltır.</span><span class="sxs-lookup"><span data-stu-id="8cd1e-197">This reduces the need for catching an exception thrown by the <xref:System.IO.File.OpenText%2A> method.</span></span>

[!code-vb[VbVbalrStatements#94](~/samples/snippets/visualbasic/VS_Snippets_VBCSharp/VbVbalrStatements/VB/Class1.vb#94)]

<span data-ttu-id="8cd1e-198">`Catch` bloklardaki kodun, iş parçacığı güvenli günlüğe kaydetme veya uygun iletiler aracılığıyla kullanıcılara özel durumları düzgün şekilde bildirediğinden emin olun.</span><span class="sxs-lookup"><span data-stu-id="8cd1e-198">Ensure that code in `Catch` blocks can properly report exceptions to users, whether through thread-safe logging or appropriate messages.</span></span> <span data-ttu-id="8cd1e-199">Aksi takdirde, özel durumlar bilinmiyor olarak kalabilir.</span><span class="sxs-lookup"><span data-stu-id="8cd1e-199">Otherwise, exceptions might remain unknown.</span></span>

## <a name="async-methods"></a><span data-ttu-id="8cd1e-200">Zaman uyumsuz yöntemler</span><span class="sxs-lookup"><span data-stu-id="8cd1e-200">Async methods</span></span>

<span data-ttu-id="8cd1e-201">[Zaman uyumsuz](../modifiers/async.md) değiştiriciyle bir yöntemi işaretlerseniz, yönteminde [await](../operators/await-operator.md) işlecini kullanabilirsiniz.</span><span class="sxs-lookup"><span data-stu-id="8cd1e-201">If you mark a method with the [Async](../modifiers/async.md) modifier, you can use the [Await](../operators/await-operator.md) operator in the method.</span></span> <span data-ttu-id="8cd1e-202">`Await` işleci olan bir ifade, beklenen görev tamamlanana kadar yöntemi yürütmeyi askıya alır.</span><span class="sxs-lookup"><span data-stu-id="8cd1e-202">A statement with the `Await` operator suspends execution of the method until the awaited task completes.</span></span> <span data-ttu-id="8cd1e-203">Görev, devam eden işi temsil eder.</span><span class="sxs-lookup"><span data-stu-id="8cd1e-203">The task represents ongoing work.</span></span> <span data-ttu-id="8cd1e-204">`Await` işleci ile ilişkili görev tamamlandığında, yürütme aynı yöntemde devam eder.</span><span class="sxs-lookup"><span data-stu-id="8cd1e-204">When the task that's associated with the `Await` operator finishes, execution resumes in the same method.</span></span> <span data-ttu-id="8cd1e-205">Daha fazla bilgi için bkz. [zaman uyumsuz programlarda denetim akışı](../../../visual-basic/programming-guide/concepts/async/control-flow-in-async-programs.md).</span><span class="sxs-lookup"><span data-stu-id="8cd1e-205">For more information, see [Control Flow in Async Programs](../../../visual-basic/programming-guide/concepts/async/control-flow-in-async-programs.md).</span></span>

<span data-ttu-id="8cd1e-206">Zaman uyumsuz bir yöntem tarafından döndürülen bir görev, işlenmemiş bir özel durum nedeniyle tamamlanmadığını belirten hatalı bir durumda bitemeyebilir.</span><span class="sxs-lookup"><span data-stu-id="8cd1e-206">A task returned by an Async method may end in a faulted state, indicating that it completed due to an unhandled exception.</span></span> <span data-ttu-id="8cd1e-207">Bir görev iptal edildi durumunda da bitebileceği için, await ifadesinin dışında bir `OperationCanceledException` oluşur.</span><span class="sxs-lookup"><span data-stu-id="8cd1e-207">A task may also end in a canceled state, which results in an `OperationCanceledException` being thrown out of the await expression.</span></span> <span data-ttu-id="8cd1e-208">Her iki özel durum türünü yakalamak için, görevle ilişkili `Await` ifadesini bir `Try` bloğunda yerleştirin ve özel durumu `Catch` bloğunda yakalayın.</span><span class="sxs-lookup"><span data-stu-id="8cd1e-208">To catch either type of exception, place the `Await` expression that's associated with the task in a `Try` block, and catch the exception in the `Catch` block.</span></span> <span data-ttu-id="8cd1e-209">Bu konunun ilerleyen kısımlarında bir örnek verilmiştir.</span><span class="sxs-lookup"><span data-stu-id="8cd1e-209">An example is provided later in this topic.</span></span>

<span data-ttu-id="8cd1e-210">Bir görev hatalı bir durumda olabilir, çünkü hatalı bir şekilde birden çok özel durum sorumludur.</span><span class="sxs-lookup"><span data-stu-id="8cd1e-210">A task can be in a faulted state because multiple exceptions were responsible for its faulting.</span></span> <span data-ttu-id="8cd1e-211">Örneğin, görev bir <xref:System.Threading.Tasks.Task.WhenAll%2A?displayProperty=nameWithType>çağrısının sonucu olabilir.</span><span class="sxs-lookup"><span data-stu-id="8cd1e-211">For example, the task might be the result of a call to <xref:System.Threading.Tasks.Task.WhenAll%2A?displayProperty=nameWithType>.</span></span> <span data-ttu-id="8cd1e-212">Böyle bir görevi bekleyolduğunuzda, yakalanan özel durum yalnızca özel durumlardan biridir ve hangi özel durumun yakalanıp yakalanmayacak olduğunu tahmin edemeyecektir.</span><span class="sxs-lookup"><span data-stu-id="8cd1e-212">When you await such a task, the caught exception is only one of the exceptions, and you can't predict which exception will be caught.</span></span> <span data-ttu-id="8cd1e-213">Bu konunun ilerleyen kısımlarında bir örnek verilmiştir.</span><span class="sxs-lookup"><span data-stu-id="8cd1e-213">An example is provided later in this topic.</span></span>

<span data-ttu-id="8cd1e-214">`Await` ifadesi `Catch` bloğu veya `Finally` bloğu içinde olamaz.</span><span class="sxs-lookup"><span data-stu-id="8cd1e-214">An `Await` expression can't be inside a `Catch` block or `Finally` block.</span></span>

## <a name="iterators"></a><span data-ttu-id="8cd1e-215">Yineleyiciler</span><span class="sxs-lookup"><span data-stu-id="8cd1e-215">Iterators</span></span>

<span data-ttu-id="8cd1e-216">Yineleyici işlevi veya `Get` erişimcisi bir koleksiyon üzerinde özel bir yineleme gerçekleştirir.</span><span class="sxs-lookup"><span data-stu-id="8cd1e-216">An iterator function or `Get` accessor performs a custom iteration over a collection.</span></span> <span data-ttu-id="8cd1e-217">Bir yineleyici, tek seferde koleksiyonun her bir öğesini döndürmek için bir [yield](yield-statement.md) ifadesini kullanır.</span><span class="sxs-lookup"><span data-stu-id="8cd1e-217">An iterator uses a [Yield](yield-statement.md) statement to return each element of the collection one at a time.</span></span> <span data-ttu-id="8cd1e-218">Her biri Için bir kullanarak bir yineleyici işlevi çağırın [... Sonraki Ifade](for-each-next-statement.md).</span><span class="sxs-lookup"><span data-stu-id="8cd1e-218">You call an iterator function by using a [For Each...Next Statement](for-each-next-statement.md).</span></span>

<span data-ttu-id="8cd1e-219">`Yield` bir ifade `Try` bloğunun içinde olabilir.</span><span class="sxs-lookup"><span data-stu-id="8cd1e-219">A `Yield` statement can be inside a `Try` block.</span></span> <span data-ttu-id="8cd1e-220">Bir `Yield` ifadesini içeren `Try` bloğu `Catch` bloklara sahip olabilir ve bir `Finally` bloğuna sahip olabilir.</span><span class="sxs-lookup"><span data-stu-id="8cd1e-220">A `Try` block that contains a `Yield` statement can have `Catch` blocks, and can have a `Finally` block.</span></span> <span data-ttu-id="8cd1e-221">Bir örnek için [yineleyicilerin](../../programming-guide/concepts/iterators.md) "Visual Basic blokları dene" bölümüne bakın.</span><span class="sxs-lookup"><span data-stu-id="8cd1e-221">See the "Try Blocks in Visual Basic" section of [Iterators](../../programming-guide/concepts/iterators.md) for an example.</span></span>

<span data-ttu-id="8cd1e-222">`Yield` bir ifade `Catch` bloğunun veya `Finally` bloğunun içinde olamaz.</span><span class="sxs-lookup"><span data-stu-id="8cd1e-222">A `Yield` statement cannot be inside a `Catch` block or a `Finally` block.</span></span>

<span data-ttu-id="8cd1e-223">`For Each` gövdesi (Yineleyici işlevi dışında) bir özel durum oluşturursa, yineleyici işlevindeki bir `Catch` bloğu yürütülmez, ancak Yineleyici işlevindeki bir `Finally` bloğu yürütülür.</span><span class="sxs-lookup"><span data-stu-id="8cd1e-223">If the `For Each` body (outside of the iterator function) throws an exception, a `Catch` block in the iterator function is not executed, but a `Finally` block in the iterator function is executed.</span></span> <span data-ttu-id="8cd1e-224">Yineleyici işlevi içindeki bir `Catch` bloğu yalnızca Yineleyici işlevinin içinde oluşan özel durumları yakalar.</span><span class="sxs-lookup"><span data-stu-id="8cd1e-224">A `Catch` block inside an iterator function catches only exceptions that occur inside the iterator function.</span></span>

## <a name="partial-trust-situations"></a><span data-ttu-id="8cd1e-225">Kısmi güven durumları</span><span class="sxs-lookup"><span data-stu-id="8cd1e-225">Partial-trust situations</span></span>

<span data-ttu-id="8cd1e-226">Bir ağ paylaşımında barındırılan bir uygulama gibi kısmi güven durumlarında `Try...Catch...Finally`, çağrıyı içeren yöntemden önce oluşan güvenlik özel durumlarını yakalamaz.</span><span class="sxs-lookup"><span data-stu-id="8cd1e-226">In partial-trust situations, such as an application hosted on a network share, `Try...Catch...Finally` does not catch security exceptions that occur before the method that contains the call is invoked.</span></span> <span data-ttu-id="8cd1e-227">Aşağıdaki örnek, bir sunucu paylaşımında yerleştirip buradan çalıştırdığınızda "System. Security. SecurityException: Istek başarısız oldu" hatasını üretir.</span><span class="sxs-lookup"><span data-stu-id="8cd1e-227">The following example, when you put it on a server share and run from there, produces the error "System.Security.SecurityException: Request Failed."</span></span> <span data-ttu-id="8cd1e-228">Güvenlik özel durumları hakkında daha fazla bilgi için <xref:System.Security.SecurityException> sınıfına bakın.</span><span class="sxs-lookup"><span data-stu-id="8cd1e-228">For more information about security exceptions, see the <xref:System.Security.SecurityException> class.</span></span>

[!code-vb[VbVbalrStatements#85](~/samples/snippets/visualbasic/VS_Snippets_VBCSharp/VbVbalrStatements/VB/Class1.vb#85)]

<span data-ttu-id="8cd1e-229">Böyle bir kısmi güven durumunda `Process.Start` ifadesini ayrı bir `Sub`yerleştirmeniz gerekir.</span><span class="sxs-lookup"><span data-stu-id="8cd1e-229">In such a partial-trust situation, you have to put the `Process.Start` statement in a separate `Sub`.</span></span> <span data-ttu-id="8cd1e-230">`Sub` ilk çağrısı başarısız olur.</span><span class="sxs-lookup"><span data-stu-id="8cd1e-230">The initial call to the `Sub` will fail.</span></span> <span data-ttu-id="8cd1e-231">Bu, `Try...Catch`, `Process.Start` içeren `Sub` ve güvenlik özel durumu üretilmadan önce yakalayıp yakalamayacağını sağlar.</span><span class="sxs-lookup"><span data-stu-id="8cd1e-231">This enables `Try...Catch` to catch it before the `Sub` that contains `Process.Start` is started and the security exception produced.</span></span>

## <a name="examples"></a><span data-ttu-id="8cd1e-232">Örnekler</span><span class="sxs-lookup"><span data-stu-id="8cd1e-232">Examples</span></span>

### <a name="the-structure-of-trycatchfinally"></a><span data-ttu-id="8cd1e-233">TRY yapısı... Yakala... Son olarak</span><span class="sxs-lookup"><span data-stu-id="8cd1e-233">The structure of Try...Catch...Finally</span></span>

<span data-ttu-id="8cd1e-234">Aşağıdaki örnek `Try...Catch...Finally` deyimin yapısını gösterir.</span><span class="sxs-lookup"><span data-stu-id="8cd1e-234">The following example illustrates the structure of the `Try...Catch...Finally` statement.</span></span>

[!code-vb[VbVbalrStatements#86](~/samples/snippets/visualbasic/VS_Snippets_VBCSharp/VbVbalrStatements/VB/Class1.vb#86)]  

### <a name="exception-in-a-method-called-from-a-try-block"></a><span data-ttu-id="8cd1e-235">Try bloğundan çağrılan bir yöntemde özel durum</span><span class="sxs-lookup"><span data-stu-id="8cd1e-235">Exception in a method called from a Try block</span></span>

<span data-ttu-id="8cd1e-236">Aşağıdaki örnekte `CreateException` yöntemi bir `NullReferenceException`oluşturur.</span><span class="sxs-lookup"><span data-stu-id="8cd1e-236">In the following example, the `CreateException` method throws a `NullReferenceException`.</span></span> <span data-ttu-id="8cd1e-237">Özel durumu üreten kod `Try` bloğunda değil.</span><span class="sxs-lookup"><span data-stu-id="8cd1e-237">The code that generates the exception is not in a `Try` block.</span></span> <span data-ttu-id="8cd1e-238">Bu nedenle `CreateException` yöntemi özel durumu işlemez.</span><span class="sxs-lookup"><span data-stu-id="8cd1e-238">Therefore, the `CreateException` method does not handle the exception.</span></span> <span data-ttu-id="8cd1e-239">`CreateException` yöntemine yapılan çağrı bir `Try` bloğunda olduğundan `RunSample` yöntemi özel durumu işler.</span><span class="sxs-lookup"><span data-stu-id="8cd1e-239">The `RunSample` method does handle the exception because the call to the `CreateException` method is in a `Try` block.</span></span>

<span data-ttu-id="8cd1e-240">Örnek, çok sayıda özel durum türü için en çok genel olarak sıralanmış `Catch` deyimlerini içerir.</span><span class="sxs-lookup"><span data-stu-id="8cd1e-240">The example includes `Catch` statements for several types of exceptions, ordered from the most specific to the most general.</span></span>

[!code-vb[VbVbalrStatements#91](~/samples/snippets/visualbasic/VS_Snippets_VBCSharp/VbVbalrStatements/VB/Class1.vb#91)]

### <a name="the-catch-when-statement"></a><span data-ttu-id="8cd1e-241">Catch while ekstresi</span><span class="sxs-lookup"><span data-stu-id="8cd1e-241">The Catch When statement</span></span>

<span data-ttu-id="8cd1e-242">Aşağıdaki örnek, bir `Catch When` deyiminin koşullu bir ifadeye filtre uygulamak için nasıl kullanılacağını gösterir.</span><span class="sxs-lookup"><span data-stu-id="8cd1e-242">The following example shows how to use a `Catch When` statement to filter on a conditional expression.</span></span> <span data-ttu-id="8cd1e-243">Koşullu ifade `True`olarak değerlendirilirse, `Catch` bloğundaki kod çalışır.</span><span class="sxs-lookup"><span data-stu-id="8cd1e-243">If the conditional expression evaluates to `True`, the code in the `Catch` block runs.</span></span>

[!code-vb[VbVbalrStatements#92](~/samples/snippets/visualbasic/VS_Snippets_VBCSharp/VbVbalrStatements/VB/Class1.vb#92)]

### <a name="nested-try-statements"></a><span data-ttu-id="8cd1e-244">İç içe deneme deyimleri</span><span class="sxs-lookup"><span data-stu-id="8cd1e-244">Nested Try statements</span></span>

<span data-ttu-id="8cd1e-245">Aşağıdaki örnek, bir `Try` bloğunda bulunan bir `Try…Catch` bildirimine sahiptir.</span><span class="sxs-lookup"><span data-stu-id="8cd1e-245">The following example has a `Try…Catch` statement that is contained in a `Try` block.</span></span> <span data-ttu-id="8cd1e-246">İç `Catch` bloğu, `InnerException` özelliği özgün özel duruma ayarlanmış bir özel durum oluşturur.</span><span class="sxs-lookup"><span data-stu-id="8cd1e-246">The inner `Catch` block throws an exception that has its `InnerException` property set to the original exception.</span></span> <span data-ttu-id="8cd1e-247">Dış `Catch` bloğu kendi özel durumunu ve iç özel durumu raporlar.</span><span class="sxs-lookup"><span data-stu-id="8cd1e-247">The outer `Catch` block reports its own exception and the inner exception.</span></span>

[!code-vb[VbVbalrStatements#93](~/samples/snippets/visualbasic/VS_Snippets_VBCSharp/VbVbalrStatements/VB/Class1.vb#93)]

### <a name="exception-handling-for-async-methods"></a><span data-ttu-id="8cd1e-248">Zaman uyumsuz metotlar için özel durum işleme</span><span class="sxs-lookup"><span data-stu-id="8cd1e-248">Exception handling for async methods</span></span>

<span data-ttu-id="8cd1e-249">Aşağıdaki örnek, zaman uyumsuz metotlar için özel durum işlemeyi gösterir.</span><span class="sxs-lookup"><span data-stu-id="8cd1e-249">The following example illustrates exception handling for async methods.</span></span> <span data-ttu-id="8cd1e-250">Zaman uyumsuz bir görev için geçerli olan bir özel durumu yakalamak için, `Await` ifadesi çağıranın `Try` bir bloğunda ve özel durum `Catch` bloğunda yakalanır.</span><span class="sxs-lookup"><span data-stu-id="8cd1e-250">To catch an exception that applies to an async task, the `Await` expression is in a `Try` block of the caller, and the exception is caught in the `Catch` block.</span></span>

<span data-ttu-id="8cd1e-251">Özel durum işlemeyi göstermek için örnekteki `Throw New Exception` satırının açıklamasını kaldırın.</span><span class="sxs-lookup"><span data-stu-id="8cd1e-251">Uncomment the `Throw New Exception` line in the example to demonstrate exception handling.</span></span> <span data-ttu-id="8cd1e-252">Özel durum `Catch` bloğunda yakalanmışsa, görevin `IsFaulted` özelliği `True`olarak ayarlanır ve görevin `Exception.InnerException` özelliği özel duruma ayarlanır.</span><span class="sxs-lookup"><span data-stu-id="8cd1e-252">The exception is caught in the `Catch` block, the task's `IsFaulted` property is set to `True`, and the task's `Exception.InnerException` property is set to the exception.</span></span>

<span data-ttu-id="8cd1e-253">Zaman uyumsuz bir işlemi iptal ettiğinizde ne olacağını göstermek için `Throw New OperationCancelledException` çizginin açıklamasını kaldırın.</span><span class="sxs-lookup"><span data-stu-id="8cd1e-253">Uncomment the `Throw New OperationCancelledException` line to demonstrate what happens when you cancel an asynchronous process.</span></span> <span data-ttu-id="8cd1e-254">Özel durum `Catch` bloğunda yakalanır ve görevin `IsCanceled` özelliği `True`olarak ayarlanır.</span><span class="sxs-lookup"><span data-stu-id="8cd1e-254">The exception is caught in the `Catch` block, and the task's `IsCanceled` property is set to `True`.</span></span> <span data-ttu-id="8cd1e-255">Ancak, bu örnek için geçerli olmayan bazı koşullar altında, `IsFaulted` `True` olarak ayarlanır ve `IsCanceled` `False`olarak ayarlanır.</span><span class="sxs-lookup"><span data-stu-id="8cd1e-255">However, under some conditions that don't apply to this example, `IsFaulted` is set to `True` and `IsCanceled` is set to `False`.</span></span>

[!code-vb[csAsyncExceptions#1](~/samples/snippets/visualbasic/VS_Snippets_VBCSharp/csasyncexceptions/vb/class1.vb#1)]

### <a name="handling-multiple-exceptions-in-async-methods"></a><span data-ttu-id="8cd1e-256">Zaman uyumsuz metotlarda birden çok özel durumu işleme</span><span class="sxs-lookup"><span data-stu-id="8cd1e-256">Handling multiple exceptions in async methods</span></span>

<span data-ttu-id="8cd1e-257">Aşağıdaki örnekte, birden çok görevin birden çok özel durum ile sonuçlanbildiği özel durum işleme gösterilmektedir.</span><span class="sxs-lookup"><span data-stu-id="8cd1e-257">The following example illustrates exception handling where multiple tasks can result in multiple exceptions.</span></span> <span data-ttu-id="8cd1e-258">`Try` bloğunun <xref:System.Threading.Tasks.Task.WhenAll%2A?displayProperty=nameWithType> döndürülen görev için `Await` ifadesi vardır.</span><span class="sxs-lookup"><span data-stu-id="8cd1e-258">The `Try` block has the `Await` expression for the task that <xref:System.Threading.Tasks.Task.WhenAll%2A?displayProperty=nameWithType> returned.</span></span> <span data-ttu-id="8cd1e-259"><xref:System.Threading.Tasks.Task.WhenAll%2A?displayProperty=nameWithType> uygulandığı üç görev tamamlandığında görev tamamlanır.</span><span class="sxs-lookup"><span data-stu-id="8cd1e-259">The task is complete when the three tasks to which <xref:System.Threading.Tasks.Task.WhenAll%2A?displayProperty=nameWithType> is applied are complete.</span></span>

<span data-ttu-id="8cd1e-260">Üç görevin her biri özel duruma neden olur.</span><span class="sxs-lookup"><span data-stu-id="8cd1e-260">Each of the three tasks causes an exception.</span></span> <span data-ttu-id="8cd1e-261">`Catch` bloğu, `Task.WhenAll` döndürülen görevin `Exception.InnerExceptions` özelliğinde bulunan özel durumlar boyunca yinelenir.</span><span class="sxs-lookup"><span data-stu-id="8cd1e-261">The `Catch` block iterates through the exceptions, which are found in the `Exception.InnerExceptions` property of the task that `Task.WhenAll` returned.</span></span>

[!code-vb[csAsyncExceptions#3](~/samples/snippets/visualbasic/VS_Snippets_VBCSharp/csasyncexceptions/vb/class1.vb#3)]

## <a name="see-also"></a><span data-ttu-id="8cd1e-262">Ayrıca bkz.</span><span class="sxs-lookup"><span data-stu-id="8cd1e-262">See also</span></span>

- <xref:Microsoft.VisualBasic.Information.Err%2A>
- <xref:System.Exception>
- [<span data-ttu-id="8cd1e-263">Exit Deyimi</span><span class="sxs-lookup"><span data-stu-id="8cd1e-263">Exit Statement</span></span>](exit-statement.md)
- [<span data-ttu-id="8cd1e-264">On Error Deyimi</span><span class="sxs-lookup"><span data-stu-id="8cd1e-264">On Error Statement</span></span>](on-error-statement.md)
- [<span data-ttu-id="8cd1e-265">Kod Parçacıkları İçin En İyi Uygulamalar</span><span class="sxs-lookup"><span data-stu-id="8cd1e-265">Best Practices for Using Code Snippets</span></span>](/visualstudio/ide/best-practices-for-using-code-snippets)
- [<span data-ttu-id="8cd1e-266">Özel Durum İşleme</span><span class="sxs-lookup"><span data-stu-id="8cd1e-266">Exception Handling</span></span>](../../../standard/parallel-programming/exception-handling-task-parallel-library.md)
- [<span data-ttu-id="8cd1e-267">Throw Deyimi</span><span class="sxs-lookup"><span data-stu-id="8cd1e-267">Throw Statement</span></span>](throw-statement.md)
